Workbook

Sheet Resument Total - Ofertas Proyec
B2: SDATOOL | C2: Proyecto | D2: Feature | E2: Horas oferta a incurrir | F2: Horas imputadas AR (acumulado) | G2: Horas por imputar AR | H2: Horas incurridas | I2: Horas por incurrir | J2: Horas Pendientes de Ejecutar / Bolsa (a consumir) | K2: Horas bolsa (consumidas) | L2: Horas bolsa (pte consumir)
B4: SDATOOL-34546 | C4: Calypso IV. Migración Abaco a Calypso F4 Swaps. | D4: CIBRDR-953 | E4: ='Imputación TR - Proyecto-Quince'!D3 -> 225 | F4: ='Imputación TR - Proyecto-Quince'!E3 -> 225 | G4: =E4-F4 -> 0 | H4: 0 | I4: =E4-H4 -> 225
B5: SDATOOL-34546 | C5: Calypso V. Migración productos estructurados F5. | D5: CIBRDR-954 | E5: ='Imputación TR - Proyecto-Quince'!D4 -> 245 | F5: ='Imputación TR - Proyecto-Quince'!E4 -> 245 | G5: =E5-F5 -> 0 | H5: 0 | I5: =E5-H5 -> 245
B6: SDATOOL-54626 | C6: Institutional Clients Transversal Tools Plan (eClients) | D6: CIBRDR-748 | E6: ='Imputación TR - Proyecto-Quince'!D5 -> 165 | F6: ='Imputación TR - Proyecto-Quince'!E5 -> 165 | G6: =E6-F6 -> 0 | H6: 0 | I6: =E6-H6 -> 165
B7: SDATOOL-53765 | C7: Marca Emisiones MMOO | D7: NA | E7: ='Imputación TR - Proyecto-Quince'!D6 -> 0 | F7: ='Imputación TR - Proyecto-Quince'!E6 -> 0 | G7: =E7-F7 -> 0 | H7: 0 | I7: =E7-H7 -> 0 | J7: 220 | K7: 220 | L7: =J7-K7 -> 0
B8: SDATOOL-49629 | C8: BSI 2.0. Cargador genérico Legal Agreements | D8: CIBRDR-762 | E8: ='Imputación TR - Proyecto-Quince'!D7 -> 805 | F8: ='Imputación TR - Proyecto-Quince'!E7 -> 805 | G8: =E8-F8 -> 0 | H8: 0 | I8: =E8-H8 -> 805
B9: SDATOOL-46848 | C9: Institutional Clients. Onboarding. | D9: CIBRDR-718 | E9: ='Imputación TR - Proyecto-Quince'!D8 -> 645 | F9: ='Imputación TR - Proyecto-Quince'!E8 -> 645 | G9: =E9-F9 -> 0 | H9: 0 | I9: =E9-H9 -> 645
B10: SDATOOL-49742 | C10: BRS. Fase 2. Colas MQ + Control M | D10: CIBRDR-932 | E10: ='Imputación TR - Proyecto-Quince'!D9 -> 490 | F10: ='Imputación TR - Proyecto-Quince'!E9 -> 40 | G10: =E10-F10-F11-F12-F13 -> 0 | H10: 0 | I10: =E10-H10 -> 490
B11: SDATOOL-49742 | C11: BRS. Fase 2. Colas MQ + Control M | D11: CIBRDR-933 | F11: ='Imputación TR - Proyecto-Quince'!E10 -> 90
B12: SDATOOL-49742 | C12: BRS. Fase 2. Colas MQ + Control M | D12: CIBRDR-934 | F12: ='Imputación TR - Proyecto-Quince'!E11 -> 70
B13: SDATOOL-49742 | C13: BRS. Fase 2. Colas MQ + Control M | D13: CIBRDR-908 | F13: ='Imputación TR - Proyecto-Quince'!E12 -> 290
B14: SDATOOL-51125 | C14: Migración FX y MM. Apagado Midas - CLS | D14: CIBRDR-990 | E14: ='Imputación TR - Proyecto-Quince'!D13 -> 1464 | F14: ='Imputación TR - Proyecto-Quince'!E13 -> 390 | G14: =E14-F14-F15 -> 0 | H14: 0 | I14: =E14-H14 -> 1464
B15: SDATOOL-51125 | C15: Migración FX y MM. Apagado Midas - Operaciones | D15: CIBRDR-766 | F15: ='Imputación TR - Proyecto-Quince'!E14 -> 1074
B16: SDATOOL-42226 | C16: Strategic Boost Alta y Mantenimiento de Emisiones y Emisores. | D16: CIBRDR-887 | E16: ='Imputación TR - Proyecto-Quince'!D15 -> 726 | F16: ='Imputación TR - Proyecto-Quince'!E15 -> 435 | G16: =E16-F16-F17 -> 0 | H16: 0 | I16: =E16-H16 -> 726
B17: SDATOOL-42226 | C17: Strategic Boost Alta y Mantenimiento de Emisiones y Emisores. | D17: CIBRDR-888 | F17: ='Imputación TR - Proyecto-Quince'!E16 -> 291
B18: SDATOOL-51067 | C18: CTM Colombia | D18: CIBRDR-962 | E18: 180 | F18: ='Imputación TR - Proyecto-Quince'!E17 -> 65 | G18: =E18-F18-F19 -> 0 | H18: 0 | I18: =E18-H18 -> 180 | J18: 180 | K18: =F18 -> 65 | L18: =J18-K18 -> 115
B19: SDATOOL-51067 | C19: CTM Colombia | D19: CIBALERTMI-9 | F19: ='Imputación TR - Proyecto-Quince'!E18 -> 115
B20: SDATOOL-51827 | C20: Maestro emisiones | D20: CIBRDR-945 | E20: ='Imputación TR - Proyecto-Quince'!D19 -> 2200 | F20: ='Imputación TR - Proyecto-Quince'!E19 -> 612 | G20: =E20-F20-F21 -> 0 | H20: 0 | I20: =E20-H20 -> 2200
B21: SDATOOL-51827 | C21: Eventos Corporativos | D21: CIBRDR-897 | F21: ='Imputación TR - Proyecto-Quince'!E20 -> 1588
B22: SDATOOL-38779 | C22: Sec Lending_Sponsored Repo | D22: CIBRDR-994 | E22: 726 | F22: ='Imputación TR - Proyecto-Quince'!E21 -> 550 | G22: =E22-F22-F23 -> 0 | H22: 0 | I22: =E22-H22 -> 726
B23: SDATOOL-38779 | C23: Sec Lending_Sponsored Repo | D23: CIBRDR-1019 | F23: ='Imputación TR - Proyecto-Quince'!E22 -> 176
B24: SDATOOL-34723 | C24: Calypso Filter | D24: CIBRDR-1029 | E24: 129 | F24: ='Imputación TR - Proyecto-Quince'!E23 -> 129 | G24: =E24-F24 -> 0 | H24: 0 | I24: =E24-H24 -> 129
B25: SDATOOL-55461 | C25: Refinamiento Productos Entregados | D25: CIBRDR-917 | E25: 129 | F25: ='Imputación TR - Proyecto-Quince'!E24 -> 129 | G25: =E25-F25 -> 0 | I25: =E25-H25 -> 129
B26: SIN CÓDIGO | C26: Proyectos Sin Código - Soporte | D26: Soporte usuarios | E26: ='Imputación TR - Proyecto-Quince'!D25 -> NA | F26: ='Imputación TR - Proyecto-Quince'!E25 -> 4391 | G26: NA | H26: 0 | I26: NA

Sheet Imputación TR - Proyecto-Quince
A1: SDATOOL | B1: Proyecto | C1: Feature | D1: Horas oferta a incurrir | E1: Horas imputadas AR (acumulado) | F1: Horas por imputar AR | G1: 1-15 Abr | H1: 16-30 Abr | I1: 1-15 May | J1: 16-31 Mayo | K1: 1-15 Jun | L1: 16-30 Jun
A3: SDATOOL-34546 | B3: Calypso IV. Migración Abaco a Calypso F4 Swaps. | C3: CIBRDR-953 | D3: 225 | E3: =SUM(G3:L3) -> 225 | F3: =D3-E3 -> 0 | G3: =SUMIF('Imputación TR - Quincena - Pers'!E:E, C3, 'Imputación TR - Quincena - Pers'!J:J) -> 0 | H3: =SUMIF('Imputación TR - Quincena - Pers'!AE:AE,C3,'Imputación TR - Quincena - Pers'!AJ:AJ) -> 220 | I3: =SUMIF('Imputación TR - Quincena - Pers'!BE:BE,C3,'Imputación TR - Quincena - Pers'!BJ:BJ) -> 5 | J3: =SUMIF('Imputación TR - Quincena - Pers'!CE:CE,C3,'Imputación TR - Quincena - Pers'!CJ:CJ) -> 0 | K3: =SUMIF('Imputación TR - Quincena - Pers'!DF:DF,C3,'Imputación TR - Quincena - Pers'!DK:DK) -> 0 | L3: =SUMIF('Imputación TR - Quincena - Pers'!EF:EF,C3,'Imputación TR - Quincena - Pers'!EK:EK) -> 0
A4: SDATOOL-34546 | B4: Calypso V. Migración productos estructurados F5. | C4: CIBRDR-954 | D4: 245 | E4: =SUM(G4:L4) -> 245 | F4: =D4-E4 -> 0 | G4: =SUMIF('Imputación TR - Quincena - Pers'!E:E, C4, 'Imputación TR - Quincena - Pers'!J:J) -> 0 | H4: =SUMIF('Imputación TR - Quincena - Pers'!AE:AE,C4,'Imputación TR - Quincena - Pers'!AJ:AJ) -> 110 | I4: =SUMIF('Imputación TR - Quincena - Pers'!BE:BE,C4,'Imputación TR - Quincena - Pers'!BJ:BJ) -> 50 | J4: =SUMIF('Imputación TR - Quincena - Pers'!CE:CE,C4,'Imputación TR - Quincena - Pers'!CJ:CJ) -> 50 | K4: =SUMIF('Imputación TR - Quincena - Pers'!DF:DF,C4,'Imputación TR - Quincena - Pers'!DK:DK) -> 35 | L4: =SUMIF('Imputación TR - Quincena - Pers'!EF:EF,C4,'Imputación TR - Quincena - Pers'!EK:EK) -> 0
A5: SDATOOL-54626 | B5: Institutional Clients Transversal Tools Plan (eClients) | C5: CIBRDR-748 | D5: 165 | E5: =SUM(G5:L5) -> 165 | F5: =D5-E5 -> 0 | G5: =SUMIF('Imputación TR - Quincena - Pers'!E:E, C5, 'Imputación TR - Quincena - Pers'!J:J) -> 0 | H5: =SUMIF('Imputación TR - Quincena - Pers'!AE:AE,C5,'Imputación TR - Quincena - Pers'!AJ:AJ) -> 0 | I5: =SUMIF('Imputación TR - Quincena - Pers'!BE:BE,C5,'Imputación TR - Quincena - Pers'!BJ:BJ) -> 50 | J5: =SUMIF('Imputación TR - Quincena - Pers'!CE:CE,C5,'Imputación TR - Quincena - Pers'!CJ:CJ) -> 0 | K5: =SUMIF('Imputación TR - Quincena - Pers'!DF:DF,C5,'Imputación TR - Quincena - Pers'!DK:DK) -> 115 | L5: =SUMIF('Imputación TR - Quincena - Pers'!EF:EF,C5,'Imputación TR - Quincena - Pers'!EK:EK) -> 0
A6: SDATOOL-53765 | B6: Marca Emisiones MMOO | C6: NA | D6: 0 | E6: =SUM(G6:L6) -> 0 | F6: =D6-E6 -> 0 | G6: =SUMIF('Imputación TR - Quincena - Pers'!E:E, C6, 'Imputación TR - Quincena - Pers'!J:J) -> 0 | H6: =SUMIF('Imputación TR - Quincena - Pers'!AE:AE,C6,'Imputación TR - Quincena - Pers'!AJ:AJ) -> 0 | I6: =SUMIF('Imputación TR - Quincena - Pers'!BE:BE,C6,'Imputación TR - Quincena - Pers'!BJ:BJ) -> 0 | J6: =SUMIF('Imputación TR - Quincena - Pers'!CE:CE,C6,'Imputación TR - Quincena - Pers'!CJ:CJ) -> 0 | K6: =SUMIF('Imputación TR - Quincena - Pers'!DF:DF,C6,'Imputación TR - Quincena - Pers'!DK:DK) -> 0 | L6: =SUMIF('Imputación TR - Quincena - Pers'!EF:EF,C6,'Imputación TR - Quincena - Pers'!EK:EK) -> 0
A7: SDATOOL-49629 | B7: BSI 2.0. Cargador genérico Legal Agreements | C7: CIBRDR-762 | D7: 805 | E7: =SUM(G7:L7) -> 805 | F7: =D7-E7 -> 0 | G7: =SUMIF('Imputación TR - Quincena - Pers'!E:E, C7, 'Imputación TR - Quincena - Pers'!J:J) -> 60 | H7: =SUMIF('Imputación TR - Quincena - Pers'!AE:AE,C7,'Imputación TR - Quincena - Pers'!AJ:AJ) -> 165 | I7: =SUMIF('Imputación TR - Quincena - Pers'!BE:BE,C7,'Imputación TR - Quincena - Pers'!BJ:BJ) -> 300 | J7: =SUMIF('Imputación TR - Quincena - Pers'!CE:CE,C7,'Imputación TR - Quincena - Pers'!CJ:CJ) -> 200 | K7: =SUMIF('Imputación TR - Quincena - Pers'!DF:DF,C7,'Imputación TR - Quincena - Pers'!DK:DK) -> 80 | L7: =SUMIF('Imputación TR - Quincena - Pers'!EF:EF,C7,'Imputación TR - Quincena - Pers'!EK:EK) -> 0
A8: SDATOOL-46848 | B8: Institutional Clients. Onboarding. | C8: CIBRDR-718 | D8: 645 | E8: =SUM(G8:L8) -> 645 | F8: =D8-E8 -> 0 | G8: =SUMIF('Imputación TR - Quincena - Pers'!E:E, C8, 'Imputación TR - Quincena - Pers'!J:J) -> 45 | H8: =SUMIF('Imputación TR - Quincena - Pers'!AE:AE,C8,'Imputación TR - Quincena - Pers'!AJ:AJ) -> 165 | I8: =SUMIF('Imputación TR - Quincena - Pers'!BE:BE,C8,'Imputación TR - Quincena - Pers'!BJ:BJ) -> 100 | J8: =SUMIF('Imputación TR - Quincena - Pers'!CE:CE,C8,'Imputación TR - Quincena - Pers'!CJ:CJ) -> 150 | K8: =SUMIF('Imputación TR - Quincena - Pers'!DF:DF,C8,'Imputación TR - Quincena - Pers'!DK:DK) -> 185 | L8: =SUMIF('Imputación TR - Quincena - Pers'!EF:EF,C8,'Imputación TR - Quincena - Pers'!EK:EK) -> 0
A9: SDATOOL-49742 | B9: BRS. Fase 2. Colas MQ + Control M | C9: CIBRDR-932 | D9: 490 | E9: =SUM(G9:L9) -> 40 | F9: =D9-E9-E10-E11-E12 -> 0 | G9: =SUMIF('Imputación TR - Quincena - Pers'!E:E, C9, 'Imputación TR - Quincena - Pers'!J:J) -> 30 | H9: =SUMIF('Imputación TR - Quincena - Pers'!AE:AE,C9,'Imputación TR - Quincena - Pers'!AJ:AJ) -> 10 | I9: =SUMIF('Imputación TR - Quincena - Pers'!BE:BE,C9,'Imputación TR - Quincena - Pers'!BJ:BJ) -> 0 | J9: =SUMIF('Imputación TR - Quincena - Pers'!CE:CE,C9,'Imputación TR - Quincena - Pers'!CJ:CJ) -> 0 | K9: =SUMIF('Imputación TR - Quincena - Pers'!DF:DF,C9,'Imputación TR - Quincena - Pers'!DK:DK) -> 0 | L9: =SUMIF('Imputación TR - Quincena - Pers'!EF:EF,C9,'Imputación TR - Quincena - Pers'!EK:EK) -> 0
A10: SDATOOL-49742 | B10: BRS. Fase 2. Colas MQ + Control M | C10: CIBRDR-933 | E10: =SUM(G10:L10) -> 90 | G10: =SUMIF('Imputación TR - Quincena - Pers'!E:E, C10, 'Imputación TR - Quincena - Pers'!J:J) -> 0 | H10: =SUMIF('Imputación TR - Quincena - Pers'!AE:AE,C10,'Imputación TR - Quincena - Pers'!AJ:AJ) -> 40 | I10: =SUMIF('Imputación TR - Quincena - Pers'!BE:BE,C10,'Imputación TR - Quincena - Pers'!BJ:BJ) -> 50 | J10: =SUMIF('Imputación TR - Quincena - Pers'!CE:CE,C10,'Imputación TR - Quincena - Pers'!CJ:CJ) -> 0 | K10: =SUMIF('Imputación TR - Quincena - Pers'!DF:DF,C10,'Imputación TR - Quincena - Pers'!DK:DK) -> 0 | L10: =SUMIF('Imputación TR - Quincena - Pers'!EF:EF,C10,'Imputación TR - Quincena - Pers'!EK:EK) -> 0
A11: SDATOOL-49742 | B11: BRS. Fase 2. Colas MQ + Control M | C11: CIBRDR-934 | E11: =SUM(G11:L11) -> 70 | G11: =SUMIF('Imputación TR - Quincena - Pers'!E:E, C11, 'Imputación TR - Quincena - Pers'!J:J) -> 0 | H11: =SUMIF('Imputación TR - Quincena - Pers'!AE:AE,C11,'Imputación TR - Quincena - Pers'!AJ:AJ) -> 0 | I11: =SUMIF('Imputación TR - Quincena - Pers'!BE:BE,C11,'Imputación TR - Quincena - Pers'!BJ:BJ) -> 70 | J11: =SUMIF('Imputación TR - Quincena - Pers'!CE:CE,C11,'Imputación TR - Quincena - Pers'!CJ:CJ) -> 0 | K11: =SUMIF('Imputación TR - Quincena - Pers'!DF:DF,C11,'Imputación TR - Quincena - Pers'!DK:DK) -> 0 | L11: =SUMIF('Imputación TR - Quincena - Pers'!EF:EF,C11,'Imputación TR - Quincena - Pers'!EK:EK) -> 0
A12: SDATOOL-49742 | B12: BRS. Fase 2. Colas MQ + Control M | C12: CIBRDR-908 | E12: =SUM(G12:L12) -> 290 | G12: =SUMIF('Imputación TR - Quincena - Pers'!E:E, 'Imputación TR - Quincena - Pers'!BE29, 'Imputación TR - Quincena - Pers'!J:J) -> 0 | H12: =SUMIF('Imputación TR - Quincena - Pers'!AE:AE,'Imputación TR - Quincena - Pers'!BE29,'Imputación TR - Quincena - Pers'!AJ:AJ) -> 150 | I12: =SUMIF('Imputación TR - Quincena - Pers'!BE:BE,'Imputación TR - Quincena - Pers'!BE29,'Imputación TR - Quincena - Pers'!BJ:BJ) -> 48 | J12: =SUMIF('Imputación TR - Quincena - Pers'!CE:CE,'Imputación TR - Quincena - Pers'!BE29,'Imputación TR - Quincena - Pers'!CJ:CJ) -> 46 | K12: =SUMIF('Imputación TR - Quincena - Pers'!DF:DF,'Imputación TR - Quincena - Pers'!BE29,'Imputación TR - Quincena - Pers'!DK:DK) -> 46 | L12: =SUMIF('Imputación TR - Quincena - Pers'!EF:EF,'Imputación TR - Quincena - Pers'!BE29,'Imputación TR - Quincena - Pers'!EK:EK) -> 0
A13: SDATOOL-51125 | B13: Migración FX y MM. Apagado Midas - CLS | C13: CIBRDR-990 | D13: 1464 | E13: =SUM(G13:L13) -> 390 | F13: =D13-E13-E14 -> 0 | G13: =SUMIF('Imputación TR - Quincena - Pers'!E:E, C13, 'Imputación TR - Quincena - Pers'!J:J) -> 0 | H13: =SUMIF('Imputación TR - Quincena - Pers'!AE:AE,C13,'Imputación TR - Quincena - Pers'!AJ:AJ) -> 0 | I13: =SUMIF('Imputación TR - Quincena - Pers'!BE:BE,C13,'Imputación TR - Quincena - Pers'!BJ:BJ) -> 175 | J13: =SUMIF('Imputación TR - Quincena - Pers'!CE:CE,C13,'Imputación TR - Quincena - Pers'!CJ:CJ) -> 150 | K13: =SUMIF('Imputación TR - Quincena - Pers'!DF:DF,C13,'Imputación TR - Quincena - Pers'!DK:DK) -> 65 | L13: =SUMIF('Imputación TR - Quincena - Pers'!EF:EF,C13,'Imputación TR - Quincena - Pers'!EK:EK) -> 0
A14: SDATOOL-51125 | B14: Migración FX y MM. Apagado Midas - Operaciones | C14: CIBRDR-766 | E14: =SUM(G14:L14) -> 1074 | G14: =SUMIF('Imputación TR - Quincena - Pers'!E:E, C14, 'Imputación TR - Quincena - Pers'!J:J) -> 0 | H14: =SUMIF('Imputación TR - Quincena - Pers'!AE:AE,C14,'Imputación TR - Quincena - Pers'!AJ:AJ) -> 0 | I14: =SUMIF('Imputación TR - Quincena - Pers'!BE:BE,C14,'Imputación TR - Quincena - Pers'!BJ:BJ) -> 450 | J14: =SUMIF('Imputación TR - Quincena - Pers'!CE:CE,C14,'Imputación TR - Quincena - Pers'!CJ:CJ) -> 350 | K14: =SUMIF('Imputación TR - Quincena - Pers'!DF:DF,C14,'Imputación TR - Quincena - Pers'!DK:DK) -> 135 | L14: =SUMIF('Imputación TR - Quincena - Pers'!EF:EF,C14,'Imputación TR - Quincena - Pers'!EK:EK) -> 139
A15: SDATOOL-42226 | B15: Strategic Boost Alta y Mantenimiento de Emisiones y Emisores. | C15: CIBRDR-887 | D15: 726 | E15: =SUM(G15:L15) -> 435 | F15: =D15-E15-E16 -> 0 | G15: =SUMIF('Imputación TR - Quincena - Pers'!E:E, C15, 'Imputación TR - Quincena - Pers'!J:J) -> 15 | H15: =SUMIF('Imputación TR - Quincena - Pers'!AE:AE,C15,'Imputación TR - Quincena - Pers'!AJ:AJ) -> 220 | I15: =SUMIF('Imputación TR - Quincena - Pers'!BE:BE,C15,'Imputación TR - Quincena - Pers'!BJ:BJ) -> 200 | J15: =SUMIF('Imputación TR - Quincena - Pers'!CE:CE,C15,'Imputación TR - Quincena - Pers'!CJ:CJ) -> 0 | K15: =SUMIF('Imputación TR - Quincena - Pers'!DF:DF,C15,'Imputación TR - Quincena - Pers'!DK:DK) -> 0 | L15: =SUMIF('Imputación TR - Quincena - Pers'!EF:EF,C15,'Imputación TR - Quincena - Pers'!EK:EK) -> 0
A16: SDATOOL-42226 | B16: Strategic Boost Alta y Mantenimiento de Emisiones y Emisores. | C16: CIBRDR-888 | E16: =SUM(G16:L16) -> 291 | G16: =SUMIF('Imputación TR - Quincena - Pers'!E:E, C16, 'Imputación TR - Quincena - Pers'!J:J) -> 30 | H16: =SUMIF('Imputación TR - Quincena - Pers'!AE:AE,C16,'Imputación TR - Quincena - Pers'!AJ:AJ) -> 110 | I16: =SUMIF('Imputación TR - Quincena - Pers'!BE:BE,C16,'Imputación TR - Quincena - Pers'!BJ:BJ) -> 50 | J16: =SUMIF('Imputación TR - Quincena - Pers'!CE:CE,C16,'Imputación TR - Quincena - Pers'!CJ:CJ) -> 50 | K16: =SUMIF('Imputación TR - Quincena - Pers'!DF:DF,C16,'Imputación TR - Quincena - Pers'!DK:DK) -> 51 | L16: =SUMIF('Imputación TR - Quincena - Pers'!EF:EF,C16,'Imputación TR - Quincena - Pers'!EK:EK) -> 0
A17: SDATOOL-51067 | B17: CTM Colombia | C17: CIBRDR-962 | D17: 180 | E17: =SUM(G17:L17) -> 65 | F17: =D17-E17-E18 -> 0 | G17: =SUMIF('Imputación TR - Quincena - Pers'!E:E, C17, 'Imputación TR - Quincena - Pers'!J:J) -> 0 | H17: =SUMIF('Imputación TR - Quincena - Pers'!AE:AE,C17,'Imputación TR - Quincena - Pers'!AJ:AJ) -> 0 | I17: =SUMIF('Imputación TR - Quincena - Pers'!BE:BE,C17,'Imputación TR - Quincena - Pers'!BJ:BJ) -> 0 | J17: =SUMIF('Imputación TR - Quincena - Pers'!CE:CE,C17,'Imputación TR - Quincena - Pers'!CJ:CJ) -> 0 | K17: =SUMIF('Imputación TR - Quincena - Pers'!DF:DF,C17,'Imputación TR - Quincena - Pers'!DK:DK) -> 65 | L17: =SUMIF('Imputación TR - Quincena - Pers'!EF:EF,C17,'Imputación TR - Quincena - Pers'!EK:EK) -> 0
A18: SDATOOL-51067 | B18: CTM Colombia | C18: CIBALERTMI-9 | E18: =SUM(G18:L18) -> 115 | G18: =SUMIF('Imputación TR - Quincena - Pers'!E:E, C18, 'Imputación TR - Quincena - Pers'!J:J) -> 0 | H18: =SUMIF('Imputación TR - Quincena - Pers'!AE:AE,C18,'Imputación TR - Quincena - Pers'!AJ:AJ) -> 0 | I18: =SUMIF('Imputación TR - Quincena - Pers'!BE:BE,C18,'Imputación TR - Quincena - Pers'!BJ:BJ) -> 0 | J18: =SUMIF('Imputación TR - Quincena - Pers'!CE:CE,C18,'Imputación TR - Quincena - Pers'!CJ:CJ) -> 0 | K18: =SUMIF('Imputación TR - Quincena - Pers'!DF:DF,C18,'Imputación TR - Quincena - Pers'!DK:DK) -> 0 | L18: =SUMIF('Imputación TR - Quincena - Pers'!EF:EF,C18,'Imputación TR - Quincena - Pers'!EK:EK) -> 115
A19: SDATOOL-51827 | B19: Maestro emisiones | C19: CIBRDR-945 | D19: 2200 | E19: =SUM(G19:L19) -> 612 | F19: =D19-E19-E20 -> 0 | G19: =SUMIF('Imputación TR - Quincena - Pers'!E:E, C19, 'Imputación TR - Quincena - Pers'!J:J) -> 0 | H19: =SUMIF('Imputación TR - Quincena - Pers'!AE:AE,C19,'Imputación TR - Quincena - Pers'!AJ:AJ) -> 220 | I19: =SUMIF('Imputación TR - Quincena - Pers'!BE:BE,C19,'Imputación TR - Quincena - Pers'!BJ:BJ) -> 300 | J19: =SUMIF('Imputación TR - Quincena - Pers'!CE:CE,C19,'Imputación TR - Quincena - Pers'!CJ:CJ) -> 50 | K19: =SUMIF('Imputación TR - Quincena - Pers'!DF:DF,C19,'Imputación TR - Quincena - Pers'!DK:DK) -> 42 | L19: =SUMIF('Imputación TR - Quincena - Pers'!EF:EF,C19,'Imputación TR - Quincena - Pers'!EK:EK) -> 0
A20: SDATOOL-51827 | B20: Eventos Corporativos | C20: CIBRDR-897 | E20: =SUM(G20:L20) -> 1588 | G20: =SUMIF('Imputación TR - Quincena - Pers'!E:E, C20, 'Imputación TR - Quincena - Pers'!J:J) -> 90 | H20: =SUMIF('Imputación TR - Quincena - Pers'!AE:AE,C20,'Imputación TR - Quincena - Pers'!AJ:AJ) -> 330 | I20: =SUMIF('Imputación TR - Quincena - Pers'!BE:BE,C20,'Imputación TR - Quincena - Pers'!BJ:BJ) -> 525 | J20: =SUMIF('Imputación TR - Quincena - Pers'!CE:CE,C20,'Imputación TR - Quincena - Pers'!CJ:CJ) -> 500 | K20: =SUMIF('Imputación TR - Quincena - Pers'!DF:DF,C20,'Imputación TR - Quincena - Pers'!DK:DK) -> 143 | L20: =SUMIF('Imputación TR - Quincena - Pers'!EF:EF,C20,'Imputación TR - Quincena - Pers'!EK:EK) -> 0
A21: SDATOOL-38779 | B21: Sec Lending_Sponsored Repo | C21: CIBRDR-994 | D21: 726 | E21: =SUM(G21:L21) -> 550 | F21: =D21-E21-E22 -> 0 | G21: =SUMIF('Imputación TR - Quincena - Pers'!E:E, C21, 'Imputación TR - Quincena - Pers'!J:J) -> 0 | H21: =SUMIF('Imputación TR - Quincena - Pers'!AE:AE,C21,'Imputación TR - Quincena - Pers'!AJ:AJ) -> 0 | I21: =SUMIF('Imputación TR - Quincena - Pers'!BE:BE,C21,'Imputación TR - Quincena - Pers'!BJ:BJ) -> 50 | J21: =SUMIF('Imputación TR - Quincena - Pers'!CE:CE,C21,'Imputación TR - Quincena - Pers'!CJ:CJ) -> 500 | K21: =SUMIF('Imputación TR - Quincena - Pers'!DF:DF,C21,'Imputación TR - Quincena - Pers'!DK:DK) -> 0 | L21: =SUMIF('Imputación TR - Quincena - Pers'!EF:EF,C21,'Imputación TR - Quincena - Pers'!EK:EK) -> 0
A22: SDATOOL-38779 | B22: Sec Lending_Sponsored Repo | C22: CIBRDR-1019 | E22: =SUM(G22:L22) -> 176 | G22: =SUMIF('Imputación TR - Quincena - Pers'!E:E, C22, 'Imputación TR - Quincena - Pers'!J:J) -> 0 | H22: =SUMIF('Imputación TR - Quincena - Pers'!AE:AE,C22,'Imputación TR - Quincena - Pers'!AJ:AJ) -> 0 | I22: =SUMIF('Imputación TR - Quincena - Pers'!BE:BE,C22,'Imputación TR - Quincena - Pers'!BJ:BJ) -> 0 | J22: =SUMIF('Imputación TR - Quincena - Pers'!CE:CE,C22,'Imputación TR - Quincena - Pers'!CJ:CJ) -> 0 | K22: =SUMIF('Imputación TR - Quincena - Pers'!DF:DF,C22,'Imputación TR - Quincena - Pers'!DK:DK) -> 176 | L22: =SUMIF('Imputación TR - Quincena - Pers'!EF:EF,C22,'Imputación TR - Quincena - Pers'!EK:EK) -> 0
A23: SDATOOL-34723 | B23: Calypso Filter | C23: CIBRDR-1029 | D23: 129 | E23: =SUM(G23:L23) -> 129 | F23: =D23-E23 -> 0 | G23: =SUMIF('Imputación TR - Quincena - Pers'!E:E, C23, 'Imputación TR - Quincena - Pers'!J:J) -> 0 | H23: =SUMIF('Imputación TR - Quincena - Pers'!AE:AE,C23,'Imputación TR - Quincena - Pers'!AJ:AJ) -> 0 | I23: =SUMIF('Imputación TR - Quincena - Pers'!BE:BE,C23,'Imputación TR - Quincena - Pers'!BJ:BJ) -> 0 | J23: =SUMIF('Imputación TR - Quincena - Pers'!CE:CE,C23,'Imputación TR - Quincena - Pers'!CJ:CJ) -> 0 | K23: =SUMIF('Imputación TR - Quincena - Pers'!DF:DF,C23,'Imputación TR - Quincena - Pers'!DK:DK) -> 45 | L23: =SUMIF('Imputación TR - Quincena - Pers'!EF:EF,C23,'Imputación TR - Quincena - Pers'!EK:EK) -> 84
A24: SDATOOL-55461 | B24: Refinamiento Productos Entregados | C24: CIBRDR-917 | D24: 129 | E24: =SUM(G24:L24) -> 129 | F24: =D24-E24 -> 0 | G24: =SUMIF('Imputación TR - Quincena - Pers'!E:E, C24, 'Imputación TR - Quincena - Pers'!J:J) -> 0 | H24: =SUMIF('Imputación TR - Quincena - Pers'!AE:AE,C24,'Imputación TR - Quincena - Pers'!AJ:AJ) -> 0 | I24: =SUMIF('Imputación TR - Quincena - Pers'!BE:BE,C24,'Imputación TR - Quincena - Pers'!BJ:BJ) -> 0 | J24: =SUMIF('Imputación TR - Quincena - Pers'!CE:CE,C24,'Imputación TR - Quincena - Pers'!CJ:CJ) -> 0 | K24: =SUMIF('Imputación TR - Quincena - Pers'!DF:DF,C24,'Imputación TR - Quincena - Pers'!DK:DK) -> 0 | L24: =SUMIF('Imputación TR - Quincena - Pers'!EF:EF,C24,'Imputación TR - Quincena - Pers'!EK:EK) -> 129
A25: SIN CÓDIGO | B25: Proyectos Sin Código - Soporte | C25: Soporte usuarios | D25: NA | E25: =SUM(G25:L25) -> 4391 | F25: NA | G25: =SUMIF('Imputación TR - Quincena - Pers'!D:D, C25, 'Imputación TR - Quincena - Pers'!J:J) -> 1464 | H25: =SUMIF('Imputación TR - Quincena - Pers'!AD:AD,C25,'Imputación TR - Quincena - Pers'!AJ:AJ) -> 401 | I25: =SUMIF('Imputación TR - Quincena - Pers'!BD:BD,C25,'Imputación TR - Quincena - Pers'!BJ:BJ) -> 87 | J25: =SUMIF('Imputación TR - Quincena - Pers'!CD:CD,C25,'Imputación TR - Quincena - Pers'!CJ:CJ) -> 168 | K25: =SUMIF('Imputación TR - Quincena - Pers'!DE:DE,C25,'Imputación TR - Quincena - Pers'!DK:DK) -> 857 | L25: =SUMIF('Imputación TR - Quincena - Pers'!EE:EE,C25,'Imputación TR - Quincena - Pers'!EK:EK) -> 1414

Sheet Imputación TR - Quincena - Pers
A1: Persona | B1: SDATOOL | C1: Nombre Proyecto | E1: Feature/Task | F1: Otras Tecnologías | G1: Nivel 1 | H1: Nivel 2 | I1: Nivel 3 | J1: Total Horas quincena | K1: 46113 | L1: 46114 | M1: 46115 | N1: 46116 | O1: 46117 | P1: 46118 | Q1: 46119 | R1: 46120 | S1: 46121 | T1: 46122 | U1: 46123 | V1: 46124 | W1: 46125 | X1: 46126 | Y1: 46127 | AA1: Persona | AB1: SDATOOL | AC1: Nombre Proyecto | AE1: Feature/Task | AF1: Otras Tecnologías | AG1: Nivel 1 | AH1: Nivel 2 | AI1: Nivel 3 | AJ1: Total Horas quincena | AK1: 46128 | AL1: 46129 | AM1: 46130 | AN1: 46131 | AO1: 46132 | AP1: 46133 | AQ1: 46134 | AR1: 46135 | AS1: 46136 | AT1: 46137 | AU1: 46138 | AV1: 46139 | AW1: 46140 | AX1: 46141 | AY1: 46142 | BA1: Persona | BB1: SDATOOL | BC1: Nombre Proyecto | BE1: Feature/Task | BF1: Otras Tecnologías | BG1: Nivel 1 | BH1: Nivel 2 | BI1: Nivel 3 | BJ1: Total Horas quincena | BK1: 46143 | BL1: 46144 | BM1: 46145 | BN1: 46146 | BO1: 46147 | BP1: 46148 | BQ1: 46149 | BR1: 46150 | BS1: 46151 | BT1: 46152 | BU1: 46153 | BV1: 46154 | BW1: 46155 | BX1: 46156 | BY1: 46157 | CA1: Persona | CB1: SDATOOL | CC1: Nombre Proyecto | CE1: Feature/Task | CF1: Otras Tecnologías | CG1: Nivel 1 | CH1: Nivel 2 | CI1: Nivel 3 | CJ1: Total Horas quincena | CK1: 46158 | CL1: 46159 | CM1: 46160 | CN1: 46161 | CO1: 46162 | CP1: 46163 | CQ1: 46164 | CR1: 46165 | CS1: 46166 | CT1: 46167 | CU1: 46168 | CV1: 46169 | CW1: 46170 | CX1: 46171 | CY1: 46172 | CZ1: 46173 | DB1: Persona | DC1: SDATOOL | DD1: Nombre Proyecto | DF1: Feature/Task | DG1: Otras Tecnologías | DH1: Nivel 1 | DI1: Nivel 2 | DJ1: Nivel 3 | DK1: Total Horas quincena | DL1: 46174 | DM1: 46175 | DN1: 46176 | DO1: 46177 | DP1: 46178 | DQ1: 46179 | DR1: 46180 | DS1: 46181 | DT1: 46182 | DU1: 46183 | DV1: 46184 | DW1: 46185 | DX1: 46186 | DY1: 46187 | DZ1: 46188 | EB1: Persona | EC1: SDATOOL | ED1: Nombre Proyecto | EF1: Feature/Task | EG1: Otras Tecnologías | EH1: Nivel 1 | EI1: Nivel 2 | EJ1: Nivel 3 | EK1: Total Horas quincena | EL1: 46189 | EM1: 46190 | EN1: 46191 | EO1: 46192 | EP1: 46193 | EQ1: 46194 | ER1: 46195 | ES1: 46196 | ET1: 46197 | EU1: 46198 | EV1: 46199 | EW1: 46200 | EX1: 46201 | EY1: 46202 | EZ1: 46203
A2: Ángela Montero | D2: Soporte usuarios | G2: Servicios prestados a proyectos sin código | H2: Análisis y diseño (antigua fase de Diseño) | I2: - | J2: =SUM(K2:Y2) -> 87 | K2: 9 | L2: 9 | P2: 9 | Q2: 9 | R2: 9 | S2: 9 | T2: 6 | W2: 9 | X2: 9 | Y2: 9 | AA2: Ángela Montero | AB2: {=IFERROR(INDEX('Resument Total - Ofertas Proyec'!$B:$B,MATCH(AE2,'Resument Total - Ofertas Proyec'!$D:$D,0)),"")} -> SDATOOL-49742 | AC2: {=IFERROR(INDEX('Imputación TR - Proyecto-Quince'!$B:$B,MATCH(AE2,'Imputación TR - Proyecto-Quince'!$C:$C,0)),"")} -> BRS. Fase 2. Colas MQ + Control M | AE2: CIBRDR-908 | AF2: =IF(AI2="Otras Tecnologías","GoldenSource","") | AG2: Servicios prestados a proyectos con código | AH2: Análisis y diseño (antigua fase de Diseño) | AI2: =IF(OR(AH2="Codificación",AH2="Pruebas"),"Otras Tecnologías","-") -> - | AJ2: =SUM(AK2:AY2) -> 23 | AK2: 5 | AV2: 9 | AW2: 9 | BA2: Ángela Montero | BB2: {=IFERROR(INDEX('Resument Total - Ofertas Proyec'!$B:$B,MATCH(BE2,'Resument Total - Ofertas Proyec'!$D:$D,0)),"")} -> SDATOOL-51125 | BC2: {=IFERROR(INDEX('Imputación TR - Proyecto-Quince'!$B:$B,MATCH(BE2,'Imputación TR - Proyecto-Quince'!$C:$C,0)),"")} -> Migración FX y MM. Apagado Midas - CLS | BE2: CIBRDR-990 | BF2: =IF(BI2="Otras Tecnologías","GoldenSource","") | BG2: Servicios prestados a proyectos con código | BH2: Análisis y diseño (antigua fase de Diseño) | BI2: =IF(OR(BH2="Codificación",BH2="Pruebas"),"Otras Tecnologías","-") -> - | BJ2: =SUM(BK2:BY2) -> 50 | BN2: 10 | BO2: 10 | BP2: 10 | BQ2: 10 | BR2: 10 | CA2: Ángela Montero | CB2: {=IFERROR(INDEX('Resument Total - Ofertas Proyec'!$B:$B,MATCH(CE2,'Resument Total - Ofertas Proyec'!$D:$D,0)),"")} | CC2: {=IFERROR(INDEX('Imputación TR - Proyecto-Quince'!$B:$B,MATCH(CE2,'Imputación TR - Proyecto-Quince'!$C:$C,0)),"")} | CD2: Soporte usuarios | CF2: =IF(CI2="Otras Tecnologías","GoldenSource","") | CG2: Servicios prestados a proyectos sin código | CH2: Análisis y diseño (antigua fase de Diseño) | CI2: =IF(OR(CH2="Codificación",CH2="Pruebas"),"Otras Tecnologías","-") -> - | CJ2: =SUM(CK2:CZ2) -> 84 | CM2: 9 | CN2: 9 | CO2: 9 | CP2: 9 | CQ2: 6 | CT2: 9 | CU2: 9 | CV2: 9 | CW2: 9 | CX2: 6 | DB2: Ángela Montero | DC2: {=IFERROR(INDEX('Resument Total - Ofertas Proyec'!$B:$B,MATCH(DF2,'Resument Total - Ofertas Proyec'!$D:$D,0)),"")} | DD2: {=IFERROR(INDEX('Imputación TR - Proyecto-Quince'!$B:$B,MATCH(DF2,'Imputación TR - Proyecto-Quince'!$C:$C,0)),"")} | DE2: Soporte usuarios | DG2: =IF(DJ2="Otras Tecnologías","GoldenSource","") | DH2: Servicios prestados a proyectos sin código | DI2: Análisis y diseño (antigua fase de Diseño) | DJ2: =IF(OR(DI2="Codificación",DI2="Pruebas"),"Otras Tecnologías","-") -> - | DK2: =SUM(DL2:EA2) -> 69 | DL2: 9 | DM2: 9 | DN2: 9 | DO2: 9 | DP2: 6 | DS2: 9 | DT2: 9 | DU2: 9 | EB2: Ángela Montero | EC2: {=IFERROR(INDEX('Resument Total - Ofertas Proyec'!$B:$B,MATCH(EF2,'Resument Total - Ofertas Proyec'!$D:$D,0)),"")} -> SDATOOL-34723 | ED2: {=IFERROR(INDEX('Imputación TR - Proyecto-Quince'!$B:$B,MATCH(EF2,'Imputación TR - Proyecto-Quince'!$C:$C,0)),"")} -> Calypso Filter | EF2: CIBRDR-1029 | EG2: =IF(EJ2="Otras Tecnologías","GoldenSource","") | EH2: - | EJ2: =IF(OR(EI2="Codificación",EI2="Pruebas"),"Otras Tecnologías","-") -> - | EK2: =SUM(EL2:EZ2) -> 72 | EL2: 18 | EM2: 18 | EN2: 18 | EO2: 18
B3: {=IFERROR(INDEX('Imputación TR - Proyecto-Quince'!$A:$A,MATCH(E3,'Imputación TR - Proyecto-Quince'!$C:$C,0)),"")} | C3: {=IFERROR(INDEX('Imputación TR - Proyecto-Quince'!$B:$B,MATCH(E3,'Imputación TR - Proyecto-Quince'!$C:$C,0)),"")} | F3: =IF(I3="Otras Tecnologías","GoldenSource","") | I3: =IF(OR(H3="Codificación",H3="Pruebas"),"Otras Tecnologías","-") -> - | J3: =SUM(K3:Y3) -> 0 | AB3: {=IFERROR(INDEX('Resument Total - Ofertas Proyec'!$B:$B,MATCH(AE3,'Resument Total - Ofertas Proyec'!$D:$D,0)),"")} | AC3: {=IFERROR(INDEX('Imputación TR - Proyecto-Quince'!$B:$B,MATCH(AE3,'Imputación TR - Proyecto-Quince'!$C:$C,0)),"")} | AD3: Soporte usuarios | AF3: =IF(AI3="Otras Tecnologías","GoldenSource","") | AG3: Servicios prestados a proyectos sin código | AH3: Análisis y diseño (antigua fase de Diseño) | AI3: =IF(OR(AH3="Codificación",AH3="Pruebas"),"Otras Tecnologías","-") -> - | AJ3: =SUM(AK3:AY3) -> 71 | AK3: 5 | AL3: 6 | AO3: 9 | AP3: 9 | AQ3: 9 | AR3: 9 | AS3: 6 | AX3: 9 | AY3: 9 | BB3: {=IFERROR(INDEX('Resument Total - Ofertas Proyec'!$B:$B,MATCH(BE3,'Resument Total - Ofertas Proyec'!$D:$D,0)),"")} -> SDATOOL-51125 | BC3: {=IFERROR(INDEX('Imputación TR - Proyecto-Quince'!$B:$B,MATCH(BE3,'Imputación TR - Proyecto-Quince'!$C:$C,0)),"")} -> Migración FX y MM. Apagado Midas - CLS | BE3: CIBRDR-990 | BF3: =IF(BI3="Otras Tecnologías","GoldenSource","") -> GoldenSource | BG3: Servicios prestados a proyectos con código | BH3: Codificación | BI3: =IF(OR(BH3="Codificación",BH3="Pruebas"),"Otras Tecnologías","-") -> Otras Tecnologías | BJ3: =SUM(BK3:BY3) -> 50 | BN3: 5 | BO3: 5 | BP3: 5 | BQ3: 5 | BR3: 5 | BU3: 5 | BV3: 5 | BW3: 5 | BX3: 5 | BY3: 5 | CB3: {=IFERROR(INDEX('Resument Total - Ofertas Proyec'!$B:$B,MATCH(CE3,'Resument Total - Ofertas Proyec'!$D:$D,0)),"")} | CC3: {=IFERROR(INDEX('Imputación TR - Proyecto-Quince'!$B:$B,MATCH(CE3,'Imputación TR - Proyecto-Quince'!$C:$C,0)),"")} | CF3: =IF(CI3="Otras Tecnologías","GoldenSource","") | CG3: - | CI3: =IF(OR(CH3="Codificación",CH3="Pruebas"),"Otras Tecnologías","-") -> - | CJ3: =SUM(CK3:CZ3) -> 0 | DC3: {=IFERROR(INDEX('Resument Total - Ofertas Proyec'!$B:$B,MATCH(DF3,'Resument Total - Ofertas Proyec'!$D:$D,0)),"")} -> SDATOOL-34723 | DD3: {=IFERROR(INDEX('Imputación TR - Proyecto-Quince'!$B:$B,MATCH(DF3,'Imputación TR - Proyecto-Quince'!$C:$C,0)),"")} -> Calypso Filter | DF3: CIBRDR-1029 | DG3: =IF(DJ3="Otras Tecnologías","GoldenSource","") | DH3: Servicios prestados a proyectos con código | DI3: Análisis y diseño (antigua fase de Diseño) | DJ3: =IF(OR(DI3="Codificación",DI3="Pruebas"),"Otras Tecnologías","-") -> - | DK3: =SUM(DL3:EA3) -> 45 | DV3: 15 | DW3: 15 | DZ3: 15 | EC3: {=IFERROR(INDEX('Resument Total - Ofertas Proyec'!$B:$B,MATCH(EF3,'Resument Total - Ofertas Proyec'!$D:$D,0)),"")} | ED3: {=IFERROR(INDEX('Imputación TR - Proyecto-Quince'!$B:$B,MATCH(EF3,'Imputación TR - Proyecto-Quince'!$C:$C,0)),"")} | EE3: Soporte usuarios | EG3: =IF(EJ3="Otras Tecnologías","GoldenSource","") | EH3: Servicios prestados a proyectos sin código | EI3: Análisis y diseño (antigua fase de Diseño) | EJ3: =IF(OR(EI3="Codificación",EI3="Pruebas"),"Otras Tecnologías","-") -> - | EK3: =SUM(EL3:EZ3) -> 60 | ER3: 9 | ES3: 9 | ET3: 9 | EU3: 9 | EV3: 6 | EY3: 9 | EZ3: 9
BB4: {=IFERROR(INDEX('Resument Total - Ofertas Proyec'!$B:$B,MATCH(BE4,'Resument Total - Ofertas Proyec'!$D:$D,0)),"")} -> SDATOOL-38779 | BC4: {=IFERROR(INDEX('Imputación TR - Proyecto-Quince'!$B:$B,MATCH(BE4,'Imputación TR - Proyecto-Quince'!$C:$C,0)),"")} -> Sec Lending_Sponsored Repo | BE4: CIBRDR-994 | BG4: Servicios prestados a proyectos con código | BH4: Análisis y diseño (antigua fase de Diseño) | BJ4: =SUM(BK4:BY4) -> 50 | BU4: 10 | BV4: 10 | BW4: 10 | BX4: 10 | BY4: 10 | EG4: =IF(EJ4="Otras Tecnologías","GoldenSource","")
A5: Chema Martinez | B5: {=IFERROR(INDEX('Imputación TR - Proyecto-Quince'!$A:$A,MATCH(E5,'Imputación TR - Proyecto-Quince'!$C:$C,0)),"")} | D5: Soporte usuarios | G5: Servicios prestados a proyectos sin código | H5: Análisis y diseño (antigua fase de Diseño) | I5: - | J5: =SUM(K5:Y5) -> 87 | K5: 9 | L5: 9 | P5: 9 | Q5: 9 | R5: 9 | S5: 9 | T5: 6 | W5: 9 | X5: 9 | Y5: 9 | AA5: Chema Martinez | AB5: {=IFERROR(INDEX('Resument Total - Ofertas Proyec'!$B:$B,MATCH(AE5,'Resument Total - Ofertas Proyec'!$D:$D,0)),"")} -> SDATOOL-51827 | AC5: {=IFERROR(INDEX('Imputación TR - Proyecto-Quince'!$B:$B,MATCH(AE5,'Imputación TR - Proyecto-Quince'!$C:$C,0)),"")} -> Maestro emisiones | AE5: CIBRDR-945 | AF5: =IF(AI5="Otras Tecnologías","GoldenSource","") | AG5: Servicios prestados a proyectos con código | AH5: Análisis y diseño (antigua fase de Diseño) | AI5: =IF(OR(AH5="Codificación",AH5="Pruebas"),"Otras Tecnologías","-") -> - | AJ5: =SUM(AK5:AY5) -> 110 | AK5: 10 | AL5: 10 | AO5: 10 | AP5: 10 | AQ5: 10 | AR5: 10 | AS5: 10 | AV5: 10 | AW5: 10 | AX5: 10 | AY5: 10 | BA5: Chema Martinez | BB5: {=IFERROR(INDEX('Resument Total - Ofertas Proyec'!$B:$B,MATCH(BE5,'Resument Total - Ofertas Proyec'!$D:$D,0)),"")} -> SDATOOL-51827 | BC5: {=IFERROR(INDEX('Imputación TR - Proyecto-Quince'!$B:$B,MATCH(BE5,'Imputación TR - Proyecto-Quince'!$C:$C,0)),"")} -> Maestro emisiones | BE5: CIBRDR-945 | BF5: =IF(BI5="Otras Tecnologías","GoldenSource","") -> GoldenSource | BG5: Servicios prestados a proyectos con código | BH5: Codificación | BI5: =IF(OR(BH5="Codificación",BH5="Pruebas"),"Otras Tecnologías","-") -> Otras Tecnologías | BJ5: =SUM(BK5:BY5) -> 150 | BN5: 15 | BO5: 15 | BP5: 15 | BQ5: 15 | BR5: 15 | BU5: 15 | BV5: 15 | BW5: 15 | BX5: 15 | BY5: 15 | CA5: Chema Martinez | CB5: {=IFERROR(INDEX('Resument Total - Ofertas Proyec'!$B:$B,MATCH(CE5,'Resument Total - Ofertas Proyec'!$D:$D,0)),"")} -> SDATOOL-51827 | CC5: {=IFERROR(INDEX('Imputación TR - Proyecto-Quince'!$B:$B,MATCH(CE5,'Imputación TR - Proyecto-Quince'!$C:$C,0)),"")} -> Eventos Corporativos | CE5: CIBRDR-897 | CF5: =IF(CI5="Otras Tecnologías","GoldenSource","") -> GoldenSource | CG5: Servicios prestados a proyectos con código | CH5: Codificación | CI5: =IF(OR(CH5="Codificación",CH5="Pruebas"),"Otras Tecnologías","-") -> Otras Tecnologías | CJ5: =SUM(CK5:CZ5) -> 150 | CM5: 15 | CN5: 15 | CO5: 15 | CP5: 15 | CQ5: 15 | CT5: 15 | CU5: 15 | CV5: 15 | CW5: 15 | CX5: 15 | DB5: Chema Martinez | DC5: {=IFERROR(INDEX('Resument Total - Ofertas Proyec'!$B:$B,MATCH(DF5,'Resument Total - Ofertas Proyec'!$D:$D,0)),"")} -> SDATOOL-46848 | DD5: {=IFERROR(INDEX('Imputación TR - Proyecto-Quince'!$B:$B,MATCH(DF5,'Imputación TR - Proyecto-Quince'!$C:$C,0)),"")} -> Institutional Clients. Onboarding. | DF5: CIBRDR-718 | DG5: =IF(DJ5="Otras Tecnologías","GoldenSource","") -> GoldenSource | DH5: Servicios prestados a proyectos con código | DI5: Pruebas | DJ5: =IF(OR(DI5="Codificación",DI5="Pruebas"),"Otras Tecnologías","-") -> Otras Tecnologías | DK5: =SUM(DL5:EA5) -> 75 | DL5: 15 | DM5: 15 | DN5: 15 | DO5: 15 | DP5: 15 | EB5: Chema Martinez | EC5: {=IFERROR(INDEX('Resument Total - Ofertas Proyec'!$B:$B,MATCH(EF5,'Resument Total - Ofertas Proyec'!$D:$D,0)),"")} -> SDATOOL-55461 | ED5: {=IFERROR(INDEX('Imputación TR - Proyecto-Quince'!$B:$B,MATCH(EF5,'Imputación TR - Proyecto-Quince'!$C:$C,0)),"")} -> Refinamiento Productos Entregados | EF5: CIBRDR-917 | EG5: =IF(EJ5="Otras Tecnologías","GoldenSource","") | EH5: Servicios prestados a proyectos con código | EI5: Análisis y diseño (antigua fase de Diseño) | EJ5: =IF(OR(EI5="Codificación",EI5="Pruebas"),"Otras Tecnologías","-") -> - | EK5: =SUM(EL5:EZ5) -> 45 | EL5: 15 | EM5: 10 | EN5: 10 | EO5: 10
B6: {=IFERROR(INDEX('Imputación TR - Proyecto-Quince'!$A:$A,MATCH(E6,'Imputación TR - Proyecto-Quince'!$C:$C,0)),"")} | C6: {=IFERROR(INDEX('Imputación TR - Proyecto-Quince'!$B:$B,MATCH(E6,'Imputación TR - Proyecto-Quince'!$C:$C,0)),"")} | F6: =IF(I6="Otras Tecnologías","GoldenSource","") | G6: - | I6: =IF(OR(H6="Codificación",H6="Pruebas"),"Otras Tecnologías","-") -> - | J6: =SUM(K6:Y6) -> 0 | AB6: {=IFERROR(INDEX('Resument Total - Ofertas Proyec'!$B:$B,MATCH(AE6,'Resument Total - Ofertas Proyec'!$D:$D,0)),"")} | AC6: {=IFERROR(INDEX('Imputación TR - Proyecto-Quince'!$B:$B,MATCH(AE6,'Imputación TR - Proyecto-Quince'!$C:$C,0)),"")} | AF6: =IF(AI6="Otras Tecnologías","GoldenSource","") | AG6: - | AI6: =IF(OR(AH6="Codificación",AH6="Pruebas"),"Otras Tecnologías","-") -> - | AJ6: =SUM(AK6:AY6) -> 0 | BB6: {=IFERROR(INDEX('Resument Total - Ofertas Proyec'!$B:$B,MATCH(BE6,'Resument Total - Ofertas Proyec'!$D:$D,0)),"")} | BC6: {=IFERROR(INDEX('Imputación TR - Proyecto-Quince'!$B:$B,MATCH(BE6,'Imputación TR - Proyecto-Quince'!$C:$C,0)),"")} | BF6: =IF(BI6="Otras Tecnologías","GoldenSource","") | BG6: - | BI6: =IF(OR(BH6="Codificación",BH6="Pruebas"),"Otras Tecnologías","-") -> - | BJ6: =SUM(BK6:BY6) -> 0 | CB6: {=IFERROR(INDEX('Resument Total - Ofertas Proyec'!$B:$B,MATCH(CE6,'Resument Total - Ofertas Proyec'!$D:$D,0)),"")} | CC6: {=IFERROR(INDEX('Imputación TR - Proyecto-Quince'!$B:$B,MATCH(CE6,'Imputación TR - Proyecto-Quince'!$C:$C,0)),"")} | CF6: =IF(CI6="Otras Tecnologías","GoldenSource","") | CG6: - | CI6: =IF(OR(CH6="Codificación",CH6="Pruebas"),"Otras Tecnologías","-") -> - | CJ6: =SUM(CK6:CZ6) -> 0 | DC6: {=IFERROR(INDEX('Resument Total - Ofertas Proyec'!$B:$B,MATCH(DF6,'Resument Total - Ofertas Proyec'!$D:$D,0)),"")} | DD6: {=IFERROR(INDEX('Imputación TR - Proyecto-Quince'!$B:$B,MATCH(DF6,'Imputación TR - Proyecto-Quince'!$C:$C,0)),"")} | DE6: Soporte usuarios | DG6: =IF(DJ6="Otras Tecnologías","GoldenSource","") | DH6: Servicios prestados a proyectos sin código | DI6: Análisis y diseño (antigua fase de Diseño) | DJ6: =IF(OR(DI6="Codificación",DI6="Pruebas"),"Otras Tecnologías","-") -> - | DK6: =SUM(DL6:EA6) -> 51 | DS6: 9 | DT6: 9 | DU6: 9 | DV6: 9 | DW6: 6 | DZ6: 9 | EC6: {=IFERROR(INDEX('Resument Total - Ofertas Proyec'!$B:$B,MATCH(EF6,'Resument Total - Ofertas Proyec'!$D:$D,0)),"")} | ED6: {=IFERROR(INDEX('Imputación TR - Proyecto-Quince'!$B:$B,MATCH(EF6,'Imputación TR - Proyecto-Quince'!$C:$C,0)),"")} | EE6: Soporte usuarios | EG6: =IF(EJ6="Otras Tecnologías","GoldenSource","") | EH6: Servicios prestados a proyectos sin código | EI6: Análisis y diseño (antigua fase de Diseño) | EJ6: =IF(OR(EI6="Codificación",EI6="Pruebas"),"Otras Tecnologías","-") -> - | EK6: =SUM(EL6:EZ6) -> 60 | ER6: 9 | ES6: 9 | ET6: 9 | EU6: 9 | EV6: 6 | EY6: 9 | EZ6: 9
B7: {=IFERROR(INDEX('Imputación TR - Proyecto-Quince'!$A:$A,MATCH(E7,'Imputación TR - Proyecto-Quince'!$C:$C,0)),"")} | C7: {=IFERROR(INDEX('Imputación TR - Proyecto-Quince'!$B:$B,MATCH(E7,'Imputación TR - Proyecto-Quince'!$C:$C,0)),"")} | F7: =IF(I7="Otras Tecnologías","GoldenSource","") | G7: - | I7: =IF(OR(H7="Codificación",H7="Pruebas"),"Otras Tecnologías","-") -> - | J7: =SUM(K7:Y7) -> 0 | AB7: {=IFERROR(INDEX('Resument Total - Ofertas Proyec'!$B:$B,MATCH(AE7,'Resument Total - Ofertas Proyec'!$D:$D,0)),"")} | AC7: {=IFERROR(INDEX('Imputación TR - Proyecto-Quince'!$B:$B,MATCH(AE7,'Imputación TR - Proyecto-Quince'!$C:$C,0)),"")} | AF7: =IF(AI7="Otras Tecnologías","GoldenSource","") | AG7: - | AI7: =IF(OR(AH7="Codificación",AH7="Pruebas"),"Otras Tecnologías","-") -> - | AJ7: =SUM(AK7:AY7) -> 0 | BB7: {=IFERROR(INDEX('Resument Total - Ofertas Proyec'!$B:$B,MATCH(BE7,'Resument Total - Ofertas Proyec'!$D:$D,0)),"")} | BC7: {=IFERROR(INDEX('Imputación TR - Proyecto-Quince'!$B:$B,MATCH(BE7,'Imputación TR - Proyecto-Quince'!$C:$C,0)),"")} | BF7: =IF(BI7="Otras Tecnologías","GoldenSource","") | BG7: - | BI7: =IF(OR(BH7="Codificación",BH7="Pruebas"),"Otras Tecnologías","-") -> - | BJ7: =SUM(BK7:BY7) -> 0 | CB7: {=IFERROR(INDEX('Resument Total - Ofertas Proyec'!$B:$B,MATCH(CE7,'Resument Total - Ofertas Proyec'!$D:$D,0)),"")} | CC7: {=IFERROR(INDEX('Imputación TR - Proyecto-Quince'!$B:$B,MATCH(CE7,'Imputación TR - Proyecto-Quince'!$C:$C,0)),"")} | CF7: =IF(CI7="Otras Tecnologías","GoldenSource","") | CG7: - | CI7: =IF(OR(CH7="Codificación",CH7="Pruebas"),"Otras Tecnologías","-") -> - | CJ7: =SUM(CK7:CZ7) -> 0 | DC7: {=IFERROR(INDEX('Resument Total - Ofertas Proyec'!$B:$B,MATCH(DF7,'Resument Total - Ofertas Proyec'!$D:$D,0)),"")} | DD7: {=IFERROR(INDEX('Imputación TR - Proyecto-Quince'!$B:$B,MATCH(DF7,'Imputación TR - Proyecto-Quince'!$C:$C,0)),"")} | DG7: =IF(DJ7="Otras Tecnologías","GoldenSource","") | DH7: - | DJ7: =IF(OR(DI7="Codificación",DI7="Pruebas"),"Otras Tecnologías","-") -> - | DK7: =SUM(DL7:EA7) -> 0 | EC7: {=IFERROR(INDEX('Resument Total - Ofertas Proyec'!$B:$B,MATCH(EF7,'Resument Total - Ofertas Proyec'!$D:$D,0)),"")} | ED7: {=IFERROR(INDEX('Imputación TR - Proyecto-Quince'!$B:$B,MATCH(EF7,'Imputación TR - Proyecto-Quince'!$C:$C,0)),"")} | EG7: =IF(EJ7="Otras Tecnologías","GoldenSource","") | EH7: - | EJ7: =IF(OR(EI7="Codificación",EI7="Pruebas"),"Otras Tecnologías","-") -> - | EK7: =SUM(EL7:EZ7) -> 0
A8: Dariel Suárez | B8: {=IFERROR(INDEX('Imputación TR - Proyecto-Quince'!$A:$A,MATCH(E8,'Imputación TR - Proyecto-Quince'!$C:$C,0)),"")} | D8: Soporte usuarios | G8: Servicios prestados a proyectos sin código | H8: Análisis y diseño (antigua fase de Diseño) | I8: - | J8: =SUM(K8:Y8) -> 87 | K8: 9 | L8: 9 | P8: 9 | Q8: 9 | R8: 9 | S8: 9 | T8: 6 | W8: 9 | X8: 9 | Y8: 9 | AA8: Dariel Suárez | AB8: {=IFERROR(INDEX('Resument Total - Ofertas Proyec'!$B:$B,MATCH(AE8,'Resument Total - Ofertas Proyec'!$D:$D,0)),"")} -> SDATOOL-34546 | AC8: {=IFERROR(INDEX('Imputación TR - Proyecto-Quince'!$B:$B,MATCH(AE8,'Imputación TR - Proyecto-Quince'!$C:$C,0)),"")} -> Calypso V. Migración productos estructurados F5. | AE8: CIBRDR-954 | AF8: =IF(AI8="Otras Tecnologías","GoldenSource","") | AG8: Servicios prestados a proyectos con código | AH8: Análisis y diseño (antigua fase de Diseño) | AI8: =IF(OR(AH8="Codificación",AH8="Pruebas"),"Otras Tecnologías","-") -> - | AJ8: =SUM(AK8:AY8) -> 110 | AK8: 10 | AL8: 10 | AO8: 10 | AP8: 10 | AQ8: 10 | AR8: 10 | AS8: 10 | AV8: 10 | AW8: 10 | AX8: 10 | AY8: 10 | BA8: Dariel Suárez | BB8: {=IFERROR(INDEX('Resument Total - Ofertas Proyec'!$B:$B,MATCH(BE8,'Resument Total - Ofertas Proyec'!$D:$D,0)),"")} -> SDATOOL-34546 | BC8: {=IFERROR(INDEX('Imputación TR - Proyecto-Quince'!$B:$B,MATCH(BE8,'Imputación TR - Proyecto-Quince'!$C:$C,0)),"")} -> Calypso V. Migración productos estructurados F5. | BE8: CIBRDR-954 | BF8: =IF(BI8="Otras Tecnologías","GoldenSource","") | BG8: Servicios prestados a proyectos con código | BH8: Análisis y diseño (antigua fase de Diseño) | BI8: =IF(OR(BH8="Codificación",BH8="Pruebas"),"Otras Tecnologías","-") -> - | BJ8: =SUM(BK8:BY8) -> 50 | BU8: 10 | BV8: 10 | BW8: 10 | BX8: 10 | BY8: 10 | CA8: Dariel Suárez | CB8: {=IFERROR(INDEX('Resument Total - Ofertas Proyec'!$B:$B,MATCH(CE8,'Resument Total - Ofertas Proyec'!$D:$D,0)),"")} -> SDATOOL-51125 | CC8: {=IFERROR(INDEX('Imputación TR - Proyecto-Quince'!$B:$B,MATCH(CE8,'Imputación TR - Proyecto-Quince'!$C:$C,0)),"")} -> Migración FX y MM. Apagado Midas - CLS | CE8: CIBRDR-990 | CF8: =IF(CI8="Otras Tecnologías","GoldenSource","") -> GoldenSource | CG8: Servicios prestados a proyectos con código | CH8: Pruebas | CI8: =IF(OR(CH8="Codificación",CH8="Pruebas"),"Otras Tecnologías","-") -> Otras Tecnologías | CJ8: =SUM(CK8:CZ8) -> 150 | CM8: 15 | CN8: 15 | CO8: 15 | CP8: 15 | CQ8: 15 | CT8: 15 | CU8: 15 | CV8: 15 | CW8: 15 | CX8: 15 | DB8: Dariel Suárez | DC8: {=IFERROR(INDEX('Resument Total - Ofertas Proyec'!$B:$B,MATCH(DF8,'Resument Total - Ofertas Proyec'!$D:$D,0)),"")} -> SDATOOL-34546 | DD8: {=IFERROR(INDEX('Imputación TR - Proyecto-Quince'!$B:$B,MATCH(DF8,'Imputación TR - Proyecto-Quince'!$C:$C,0)),"")} -> Calypso V. Migración productos estructurados F5. | DF8: CIBRDR-954 | DG8: =IF(DJ8="Otras Tecnologías","GoldenSource","") -> GoldenSource | DH8: Servicios prestados a proyectos con código | DI8: Pruebas | DJ8: =IF(OR(DI8="Codificación",DI8="Pruebas"),"Otras Tecnologías","-") -> Otras Tecnologías | DK8: =SUM(DL8:EA8) -> 35 | DL8: 10 | DM8: 10 | DN8: 5 | DO8: 5 | DP8: 5 | EB8: Dariel Suárez | EC8: {=IFERROR(INDEX('Resument Total - Ofertas Proyec'!$B:$B,MATCH(EF8,'Resument Total - Ofertas Proyec'!$D:$D,0)),"")} -> SDATOOL-51125 | ED8: {=IFERROR(INDEX('Imputación TR - Proyecto-Quince'!$B:$B,MATCH(EF8,'Imputación TR - Proyecto-Quince'!$C:$C,0)),"")} -> Migración FX y MM. Apagado Midas - Operaciones | EF8: CIBRDR-766 | EG8: =IF(EJ8="Otras Tecnologías","GoldenSource","") | EH8: Servicios prestados a proyectos con código | EI8: Análisis y diseño (antigua fase de Diseño) | EJ8: =IF(OR(EI8="Codificación",EI8="Pruebas"),"Otras Tecnologías","-") -> - | EK8: =SUM(EL8:EZ8) -> 59 | EL8: 15 | EM8: 15 | EN8: 15 | EO8: 14
B9: {=IFERROR(INDEX('Imputación TR - Proyecto-Quince'!$A:$A,MATCH(E9,'Imputación TR - Proyecto-Quince'!$C:$C,0)),"")} | C9: {=IFERROR(INDEX('Imputación TR - Proyecto-Quince'!$B:$B,MATCH(E9,'Imputación TR - Proyecto-Quince'!$C:$C,0)),"")} | F9: =IF(I9="Otras Tecnologías","GoldenSource","") | G9: - | I9: =IF(OR(H9="Codificación",H9="Pruebas"),"Otras Tecnologías","-") -> - | J9: =SUM(K9:Y9) -> 0 | AB9: {=IFERROR(INDEX('Resument Total - Ofertas Proyec'!$B:$B,MATCH(AE9,'Resument Total - Ofertas Proyec'!$D:$D,0)),"")} | AC9: {=IFERROR(INDEX('Imputación TR - Proyecto-Quince'!$B:$B,MATCH(AE9,'Imputación TR - Proyecto-Quince'!$C:$C,0)),"")} | AF9: =IF(AI9="Otras Tecnologías","GoldenSource","") | AG9: - | AI9: =IF(OR(AH9="Codificación",AH9="Pruebas"),"Otras Tecnologías","-") -> - | AJ9: =SUM(AK9:AY9) -> 0 | BB9: {=IFERROR(INDEX('Resument Total - Ofertas Proyec'!$B:$B,MATCH(BE9,'Resument Total - Ofertas Proyec'!$D:$D,0)),"")} -> SDATOOL-51125 | BC9: {=IFERROR(INDEX('Imputación TR - Proyecto-Quince'!$B:$B,MATCH(BE9,'Imputación TR - Proyecto-Quince'!$C:$C,0)),"")} -> Migración FX y MM. Apagado Midas - CLS | BE9: CIBRDR-990 | BF9: =IF(BI9="Otras Tecnologías","GoldenSource","") -> GoldenSource | BG9: Servicios prestados a proyectos con código | BH9: Codificación | BI9: =IF(OR(BH9="Codificación",BH9="Pruebas"),"Otras Tecnologías","-") -> Otras Tecnologías | BJ9: =SUM(BK9:BY9) -> 75 | BN9: 15 | BO9: 15 | BP9: 15 | BQ9: 15 | BR9: 15 | CB9: {=IFERROR(INDEX('Resument Total - Ofertas Proyec'!$B:$B,MATCH(CE9,'Resument Total - Ofertas Proyec'!$D:$D,0)),"")} | CC9: {=IFERROR(INDEX('Imputación TR - Proyecto-Quince'!$B:$B,MATCH(CE9,'Imputación TR - Proyecto-Quince'!$C:$C,0)),"")} | CF9: =IF(CI9="Otras Tecnologías","GoldenSource","") | CG9: - | CI9: =IF(OR(CH9="Codificación",CH9="Pruebas"),"Otras Tecnologías","-") -> - | CJ9: =SUM(CK9:CZ9) -> 0 | DC9: {=IFERROR(INDEX('Resument Total - Ofertas Proyec'!$B:$B,MATCH(DF9,'Resument Total - Ofertas Proyec'!$D:$D,0)),"")} -> SDATOOL-51125 | DD9: {=IFERROR(INDEX('Imputación TR - Proyecto-Quince'!$B:$B,MATCH(DF9,'Imputación TR - Proyecto-Quince'!$C:$C,0)),"")} -> Migración FX y MM. Apagado Midas - Operaciones | DF9: CIBRDR-766 | DG9: =IF(DJ9="Otras Tecnologías","GoldenSource","") | DH9: Servicios prestados a proyectos con código | DI9: Análisis y diseño (antigua fase de Diseño) | DJ9: =IF(OR(DI9="Codificación",DI9="Pruebas"),"Otras Tecnologías","-") -> - | DK9: =SUM(DL9:EA9) -> 135 | DL9: 7 | DM9: 7 | DN9: 12 | DO9: 12 | DP9: 12 | DS9: 17 | DT9: 17 | DU9: 17 | DV9: 17 | DW9: 17 | EC9: {=IFERROR(INDEX('Resument Total - Ofertas Proyec'!$B:$B,MATCH(EF9,'Resument Total - Ofertas Proyec'!$D:$D,0)),"")} | ED9: {=IFERROR(INDEX('Imputación TR - Proyecto-Quince'!$B:$B,MATCH(EF9,'Imputación TR - Proyecto-Quince'!$C:$C,0)),"")} | EE9: Soporte usuarios | EH9: Servicios prestados a proyectos sin código | EI9: Análisis y diseño (antigua fase de Diseño) | EJ9: =IF(OR(EI9="Codificación",EI9="Pruebas"),"Otras Tecnologías","-") -> - | EK9: =SUM(EL9:EZ9) -> 60 | ER9: 9 | ES9: 9 | ET9: 9 | EU9: 9 | EV9: 6 | EY9: 9 | EZ9: 9
B10: {=IFERROR(INDEX('Imputación TR - Proyecto-Quince'!$A:$A,MATCH(E10,'Imputación TR - Proyecto-Quince'!$C:$C,0)),"")} | C10: {=IFERROR(INDEX('Imputación TR - Proyecto-Quince'!$B:$B,MATCH(E10,'Imputación TR - Proyecto-Quince'!$C:$C,0)),"")} | F10: =IF(I10="Otras Tecnologías","GoldenSource","") | G10: - | I10: =IF(OR(H10="Codificación",H10="Pruebas"),"Otras Tecnologías","-") -> - | J10: =SUM(K10:Y10) -> 0 | AB10: {=IFERROR(INDEX('Resument Total - Ofertas Proyec'!$B:$B,MATCH(AE10,'Resument Total - Ofertas Proyec'!$D:$D,0)),"")} | AC10: {=IFERROR(INDEX('Imputación TR - Proyecto-Quince'!$B:$B,MATCH(AE10,'Imputación TR - Proyecto-Quince'!$C:$C,0)),"")} | AF10: =IF(AI10="Otras Tecnologías","GoldenSource","") | AG10: - | AI10: =IF(OR(AH10="Codificación",AH10="Pruebas"),"Otras Tecnologías","-") -> - | AJ10: =SUM(AK10:AY10) -> 0 | BB10: {=IFERROR(INDEX('Resument Total - Ofertas Proyec'!$B:$B,MATCH(BE10,'Resument Total - Ofertas Proyec'!$D:$D,0)),"")} | BC10: {=IFERROR(INDEX('Imputación TR - Proyecto-Quince'!$B:$B,MATCH(BE10,'Imputación TR - Proyecto-Quince'!$C:$C,0)),"")} | BF10: =IF(BI10="Otras Tecnologías","GoldenSource","") | BG10: - | BI10: =IF(OR(BH10="Codificación",BH10="Pruebas"),"Otras Tecnologías","-") -> - | BJ10: =SUM(BK10:BY10) -> 0 | CB10: {=IFERROR(INDEX('Resument Total - Ofertas Proyec'!$B:$B,MATCH(CE10,'Resument Total - Ofertas Proyec'!$D:$D,0)),"")} | CC10: {=IFERROR(INDEX('Imputación TR - Proyecto-Quince'!$B:$B,MATCH(CE10,'Imputación TR - Proyecto-Quince'!$C:$C,0)),"")} | CF10: =IF(CI10="Otras Tecnologías","GoldenSource","") | CG10: - | CI10: =IF(OR(CH10="Codificación",CH10="Pruebas"),"Otras Tecnologías","-") -> - | CJ10: =SUM(CK10:CZ10) -> 0 | DC10: {=IFERROR(INDEX('Resument Total - Ofertas Proyec'!$B:$B,MATCH(DF10,'Resument Total - Ofertas Proyec'!$D:$D,0)),"")} | DD10: {=IFERROR(INDEX('Imputación TR - Proyecto-Quince'!$B:$B,MATCH(DF10,'Imputación TR - Proyecto-Quince'!$C:$C,0)),"")} | DE10: Soporte usuarios | DG10: =IF(DJ10="Otras Tecnologías","GoldenSource","") | DH10: Servicios prestados a proyectos sin código | DI10: Análisis y diseño (antigua fase de Diseño) | DJ10: =IF(OR(DI10="Codificación",DI10="Pruebas"),"Otras Tecnologías","-") -> - | DK10: =SUM(DL10:EA10) -> 9 | DZ10: 9 | EC10: {=IFERROR(INDEX('Resument Total - Ofertas Proyec'!$B:$B,MATCH(EF10,'Resument Total - Ofertas Proyec'!$D:$D,0)),"")} | ED10: {=IFERROR(INDEX('Imputación TR - Proyecto-Quince'!$B:$B,MATCH(EF10,'Imputación TR - Proyecto-Quince'!$C:$C,0)),"")} | EG10: =IF(EJ10="Otras Tecnologías","GoldenSource","") | EH10: - | EJ10: =IF(OR(EI10="Codificación",EI10="Pruebas"),"Otras Tecnologías","-") -> - | EK10: =SUM(EL10:EZ10) -> 0
A11: David Joel | B11: {=IFERROR(INDEX('Imputación TR - Proyecto-Quince'!$A:$A,MATCH(E11,'Imputación TR - Proyecto-Quince'!$C:$C,0)),"")} | D11: Soporte usuarios | G11: Servicios prestados a proyectos sin código | H11: Análisis y diseño (antigua fase de Diseño) | I11: - | J11: =SUM(K11:Y11) -> 87 | K11: 9 | L11: 9 | P11: 9 | Q11: 9 | R11: 9 | S11: 9 | T11: 6 | W11: 9 | X11: 9 | Y11: 9 | AA11: David Joel | AB11: {=IFERROR(INDEX('Resument Total - Ofertas Proyec'!$B:$B,MATCH(AE11,'Resument Total - Ofertas Proyec'!$D:$D,0)),"")} -> SDATOOL-51827 | AC11: {=IFERROR(INDEX('Imputación TR - Proyecto-Quince'!$B:$B,MATCH(AE11,'Imputación TR - Proyecto-Quince'!$C:$C,0)),"")} -> Eventos Corporativos | AE11: CIBRDR-897 | AF11: =IF(AI11="Otras Tecnologías","GoldenSource","") | AG11: Servicios prestados a proyectos con código | AH11: Análisis y diseño (antigua fase de Diseño) | AI11: =IF(OR(AH11="Codificación",AH11="Pruebas"),"Otras Tecnologías","-") -> - | AJ11: =SUM(AK11:AY11) -> 110 | AK11: 10 | AL11: 10 | AO11: 10 | AP11: 10 | AQ11: 10 | AR11: 10 | AS11: 10 | AV11: 10 | AW11: 10 | AX11: 10 | AY11: 10 | BA11: David Joel | BB11: {=IFERROR(INDEX('Resument Total - Ofertas Proyec'!$B:$B,MATCH(BE11,'Resument Total - Ofertas Proyec'!$D:$D,0)),"")} -> SDATOOL-51827 | BC11: {=IFERROR(INDEX('Imputación TR - Proyecto-Quince'!$B:$B,MATCH(BE11,'Imputación TR - Proyecto-Quince'!$C:$C,0)),"")} -> Eventos Corporativos | BE11: CIBRDR-897 | BF11: =IF(BI11="Otras Tecnologías","GoldenSource","") -> GoldenSource | BG11: Servicios prestados a proyectos con código | BH11: Codificación | BI11: =IF(OR(BH11="Codificación",BH11="Pruebas"),"Otras Tecnologías","-") -> Otras Tecnologías | BJ11: =SUM(BK11:BY11) -> 150 | BN11: 15 | BO11: 15 | BP11: 15 | BQ11: 15 | BR11: 15 | BU11: 15 | BV11: 15 | BW11: 15 | BX11: 15 | BY11: 15 | CA11: David Joel | CB11: {=IFERROR(INDEX('Resument Total - Ofertas Proyec'!$B:$B,MATCH(CE11,'Resument Total - Ofertas Proyec'!$D:$D,0)),"")} -> SDATOOL-38779 | CC11: {=IFERROR(INDEX('Imputación TR - Proyecto-Quince'!$B:$B,MATCH(CE11,'Imputación TR - Proyecto-Quince'!$C:$C,0)),"")} -> Sec Lending_Sponsored Repo | CE11: CIBRDR-994 | CF11: =IF(CI11="Otras Tecnologías","GoldenSource","") -> GoldenSource | CG11: Servicios prestados a proyectos con código | CH11: Codificación | CI11: =IF(OR(CH11="Codificación",CH11="Pruebas"),"Otras Tecnologías","-") -> Otras Tecnologías | CJ11: =SUM(CK11:CZ11) -> 150 | CM11: 15 | CN11: 15 | CO11: 15 | CP11: 15 | CQ11: 15 | CT11: 15 | CU11: 15 | CV11: 15 | CW11: 15 | CX11: 15 | DB11: David Joel | DC11: {=IFERROR(INDEX('Resument Total - Ofertas Proyec'!$B:$B,MATCH(DF11,'Resument Total - Ofertas Proyec'!$D:$D,0)),"")} -> SDATOOL-46848 | DD11: {=IFERROR(INDEX('Imputación TR - Proyecto-Quince'!$B:$B,MATCH(DF11,'Imputación TR - Proyecto-Quince'!$C:$C,0)),"")} -> Institutional Clients. Onboarding. | DF11: CIBRDR-718 | DG11: =IF(DJ11="Otras Tecnologías","GoldenSource","") -> GoldenSource | DH11: Servicios prestados a proyectos con código | DI11: Pruebas | DJ11: =IF(OR(DI11="Codificación",DI11="Pruebas"),"Otras Tecnologías","-") -> Otras Tecnologías | DK11: =SUM(DL11:EA11) -> 35 | DL11: 10 | DM11: 10 | DN11: 10 | DO11: 5 | EB11: David Joel | EC11: {=IFERROR(INDEX('Resument Total - Ofertas Proyec'!$B:$B,MATCH(EF11,'Resument Total - Ofertas Proyec'!$D:$D,0)),"")} | ED11: {=IFERROR(INDEX('Imputación TR - Proyecto-Quince'!$B:$B,MATCH(EF11,'Imputación TR - Proyecto-Quince'!$C:$C,0)),"")} | EE11: Soporte usuarios | EG11: =IF(EJ11="Otras Tecnologías","GoldenSource","") | EH11: Servicios prestados a proyectos sin código | EI11: Análisis y diseño (antigua fase de Diseño) | EJ11: =IF(OR(EI11="Codificación",EI11="Pruebas"),"Otras Tecnologías","-") -> - | EK11: =SUM(EL11:EZ11) -> 93 | EL11: 9 | EM11: 9 | EN11: 9 | EO11: 6 | ER11: 9 | ES11: 9 | ET11: 9 | EU11: 9 | EV11: 6 | EY11: 9 | EZ11: 9
B12: {=IFERROR(INDEX('Imputación TR - Proyecto-Quince'!$A:$A,MATCH(E12,'Imputación TR - Proyecto-Quince'!$C:$C,0)),"")} | C12: {=IFERROR(INDEX('Imputación TR - Proyecto-Quince'!$B:$B,MATCH(E12,'Imputación TR - Proyecto-Quince'!$C:$C,0)),"")} | F12: =IF(I12="Otras Tecnologías","GoldenSource","") | G12: - | I12: =IF(OR(H12="Codificación",H12="Pruebas"),"Otras Tecnologías","-") -> - | J12: =SUM(K12:Y12) -> 0 | AB12: {=IFERROR(INDEX('Resument Total - Ofertas Proyec'!$B:$B,MATCH(AE12,'Resument Total - Ofertas Proyec'!$D:$D,0)),"")} | AC12: {=IFERROR(INDEX('Imputación TR - Proyecto-Quince'!$B:$B,MATCH(AE12,'Imputación TR - Proyecto-Quince'!$C:$C,0)),"")} | AF12: =IF(AI12="Otras Tecnologías","GoldenSource","") | AG12: - | AI12: =IF(OR(AH12="Codificación",AH12="Pruebas"),"Otras Tecnologías","-") -> - | AJ12: =SUM(AK12:AY12) -> 0 | BB12: {=IFERROR(INDEX('Resument Total - Ofertas Proyec'!$B:$B,MATCH(BE12,'Resument Total - Ofertas Proyec'!$D:$D,0)),"")} | BC12: {=IFERROR(INDEX('Imputación TR - Proyecto-Quince'!$B:$B,MATCH(BE12,'Imputación TR - Proyecto-Quince'!$C:$C,0)),"")} | BF12: =IF(BI12="Otras Tecnologías","GoldenSource","") | BI12: =IF(OR(BH12="Codificación",BH12="Pruebas"),"Otras Tecnologías","-") -> - | BJ12: =SUM(BK12:BY12) -> 0 | CB12: {=IFERROR(INDEX('Resument Total - Ofertas Proyec'!$B:$B,MATCH(CE12,'Resument Total - Ofertas Proyec'!$D:$D,0)),"")} | CC12: {=IFERROR(INDEX('Imputación TR - Proyecto-Quince'!$B:$B,MATCH(CE12,'Imputación TR - Proyecto-Quince'!$C:$C,0)),"")} | CF12: =IF(CI12="Otras Tecnologías","GoldenSource","") | CG12: - | CI12: =IF(OR(CH12="Codificación",CH12="Pruebas"),"Otras Tecnologías","-") -> - | CJ12: =SUM(CK12:CZ12) -> 0 | DC12: {=IFERROR(INDEX('Resument Total - Ofertas Proyec'!$B:$B,MATCH(DF12,'Resument Total - Ofertas Proyec'!$D:$D,0)),"")} | DD12: {=IFERROR(INDEX('Imputación TR - Proyecto-Quince'!$B:$B,MATCH(DF12,'Imputación TR - Proyecto-Quince'!$C:$C,0)),"")} | DE12: Soporte usuarios | DH12: Servicios prestados a proyectos sin código | DI12: Análisis y diseño (antigua fase de Diseño) | DJ12: Análisis y diseño (antigua fase de Diseño) | DK12: =SUM(DL12:EA12) -> 62 | DO12: 5 | DP12: 6 | DS12: 9 | DT12: 9 | DU12: 9 | DV12: 9 | DW12: 6 | DZ12: 9 | EC12: {=IFERROR(INDEX('Resument Total - Ofertas Proyec'!$B:$B,MATCH(EF12,'Resument Total - Ofertas Proyec'!$D:$D,0)),"")} | ED12: {=IFERROR(INDEX('Imputación TR - Proyecto-Quince'!$B:$B,MATCH(EF12,'Imputación TR - Proyecto-Quince'!$C:$C,0)),"")} | EG12: =IF(EJ12="Otras Tecnologías","GoldenSource","") | EH12: - | EJ12: =IF(OR(EI12="Codificación",EI12="Pruebas"),"Otras Tecnologías","-") -> - | EK12: =SUM(EL12:EZ12) -> 0
B13: {=IFERROR(INDEX('Imputación TR - Proyecto-Quince'!$A:$A,MATCH(E13,'Imputación TR - Proyecto-Quince'!$C:$C,0)),"")} | C13: {=IFERROR(INDEX('Imputación TR - Proyecto-Quince'!$B:$B,MATCH(E13,'Imputación TR - Proyecto-Quince'!$C:$C,0)),"")} | F13: =IF(I13="Otras Tecnologías","GoldenSource","") | G13: - | I13: =IF(OR(H13="Codificación",H13="Pruebas"),"Otras Tecnologías","-") -> - | J13: =SUM(K13:Y13) -> 0 | AB13: {=IFERROR(INDEX('Resument Total - Ofertas Proyec'!$B:$B,MATCH(AE13,'Resument Total - Ofertas Proyec'!$D:$D,0)),"")} | AC13: {=IFERROR(INDEX('Imputación TR - Proyecto-Quince'!$B:$B,MATCH(AE13,'Imputación TR - Proyecto-Quince'!$C:$C,0)),"")} | AF13: =IF(AI13="Otras Tecnologías","GoldenSource","") | AG13: - | AI13: =IF(OR(AH13="Codificación",AH13="Pruebas"),"Otras Tecnologías","-") -> - | AJ13: =SUM(AK13:AY13) -> 0 | BB13: {=IFERROR(INDEX('Resument Total - Ofertas Proyec'!$B:$B,MATCH(BE13,'Resument Total - Ofertas Proyec'!$D:$D,0)),"")} | BC13: {=IFERROR(INDEX('Imputación TR - Proyecto-Quince'!$B:$B,MATCH(BE13,'Imputación TR - Proyecto-Quince'!$C:$C,0)),"")} | BF13: =IF(BI13="Otras Tecnologías","GoldenSource","") | BG13: - | BI13: =IF(OR(BH13="Codificación",BH13="Pruebas"),"Otras Tecnologías","-") -> - | BJ13: =SUM(BK13:BY13) -> 0 | CB13: {=IFERROR(INDEX('Resument Total - Ofertas Proyec'!$B:$B,MATCH(CE13,'Resument Total - Ofertas Proyec'!$D:$D,0)),"")} | CC13: {=IFERROR(INDEX('Imputación TR - Proyecto-Quince'!$B:$B,MATCH(CE13,'Imputación TR - Proyecto-Quince'!$C:$C,0)),"")} | CF13: =IF(CI13="Otras Tecnologías","GoldenSource","") | CG13: - | CI13: =IF(OR(CH13="Codificación",CH13="Pruebas"),"Otras Tecnologías","-") -> - | CJ13: =SUM(CK13:CZ13) -> 0 | DC13: {=IFERROR(INDEX('Resument Total - Ofertas Proyec'!$B:$B,MATCH(DF13,'Resument Total - Ofertas Proyec'!$D:$D,0)),"")} | DD13: {=IFERROR(INDEX('Imputación TR - Proyecto-Quince'!$B:$B,MATCH(DF13,'Imputación TR - Proyecto-Quince'!$C:$C,0)),"")} | DG13: =IF(DJ13="Otras Tecnologías","GoldenSource","") | DH13: - | DJ13: =IF(OR(DI13="Codificación",DI13="Pruebas"),"Otras Tecnologías","-") -> - | DK13: =SUM(DL13:EA13) -> 0 | EC13: {=IFERROR(INDEX('Resument Total - Ofertas Proyec'!$B:$B,MATCH(EF13,'Resument Total - Ofertas Proyec'!$D:$D,0)),"")} | ED13: {=IFERROR(INDEX('Imputación TR - Proyecto-Quince'!$B:$B,MATCH(EF13,'Imputación TR - Proyecto-Quince'!$C:$C,0)),"")} | EG13: =IF(EJ13="Otras Tecnologías","GoldenSource","") | EH13: - | EJ13: =IF(OR(EI13="Codificación",EI13="Pruebas"),"Otras Tecnologías","-") -> - | EK13: =SUM(EL13:EZ13) -> 0
